Workbook

Sheet Executive Summary
A1: FINTECH STARTUP - EXECUTIVE SUMMARY
A2: Banking, Payments, FX, Lending & Personal Finance Platform
A4: BUSINESS MODEL OVERVIEW
A5: 1. Transaction Fees (Domestic & International)
A6: 2. FX Spreads (Fiat & Crypto)
A7: 3. Interchange Fees (Debit Card Program)
A8: 4. Lending Revenue (Loans, Credit Lines, Interest)
A9: 5. BNPL Merchant Fees
A10: 6. Premium Account Subscriptions
A11: 7. Net Interest Margin on Deposits
A12: 8. Investment Advisory Fees (Robo-Advisor)
A13: 9. Partner Referral Commissions
A15: KEY METRICS (Year 1)
A16: Total Users | B16: ='Financial Projections'!C6 -> 30000
A17: Monthly Active Users | B17: ='Financial Projections'!C7 -> 19500
A18: Total Revenue | B18: ='Financial Projections'!C20 -> 209601.05
A19: EBITDA | B19: ='Financial Projections'!C33 -> 0
A20: EBITDA Margin | B20: ='Financial Projections'!C34 -> 0
A22: UNIT ECONOMICS
A23: Monthly Revenue per Active User | B23: ='Unit Economics'!B20 -> 0.89587538
A24: Contribution Margin per User | B24: ='Unit Economics'!B32 -> 0.46306538
A25: Contribution Margin % | B25: ='Unit Economics'!B33 -> 0.51688593
A26: Customer Acquisition Cost | B26: ='Unit Economics'!B37 -> 0
A27: Payback Period (months) | B27: ='Unit Economics'!B38 -> 0
A28: LTV / CAC (3 year) | B28: ='Unit Economics'!B39 -> 0
A30: VALUATION
A31: Pre-Money Valuation | B31: =Valuation!B7 -> 8000000
A32: Post-Money Valuation | B32: =Valuation!B11 -> 10000000
A33: Investment Amount | B33: =Valuation!B8 -> 2000000
A34: Investor Ownership % | B34: =Valuation!B15 -> 0.2

Sheet Revenue Model
A1: FINTECH REVENUE MODEL - ASSUMPTIONS
A2: Banking, Payments, FX, Lending & Personal Finance Platform
A4: USER BASE ASSUMPTIONS
A5: Starting Users (Year 0) | B5: 10000 | C5: Initial registered users
A6: User Growth Rate Y1 (%) | B6: 2 | C6: 200% growth in year 1
A7: User Growth Rate Y2 (%) | B7: 1.5 | C7: 150% growth in year 2
A8: User Growth Rate Y3 (%) | B8: 1 | C8: 100% growth in year 3
A9: User Growth Rate Y4 (%) | B9: 0.6 | C9: 60% growth in year 4
A10: User Growth Rate Y5 (%) | B10: 0.4 | C10: 40% growth in year 5
A11: Active User Rate (%) | B11: 0.65 | C11: % of users who are monthly active
A12: Premium User Conversion (%) | B12: 0.12 | C12: % of active users on paid plans
A14: TRANSACTION FEES & FX REVENUE
A15: Avg Transactions per Active User/Month | B15: 8.5 | C15: Payment transactions per user
A16: Avg Transaction Value ($) | B16: 125 | C16: Average payment amount
A17: Transaction Fee Rate (%) | B17: 0.0275 | C17: 2.75% average fee
A18: International Transaction % of Total | B18: 0.35 | C18: 35% are cross-border
A19: International Transaction Markup (%) | B19: 0.015 | C19: Additional 1.5% on international
A21: FX Transactions per Active User/Month | B21: 2.5 | C21: Currency exchanges per user
A22: Avg FX Transaction Size ($) | B22: 450 | C22: Average FX conversion amount
A23: FX Spread (%) | B23: 0.008 | C23: 0.8% spread on FX
A24: Crypto FX % of Total | B24: 0.15 | C24: 15% involve crypto
A25: Crypto FX Spread (%) | B25: 0.025 | C25: 2.5% spread on crypto FX
A27: INTERCHANGE FEES (DEBIT CARD PROGRAM)
A28: Card Active Rate (%) | B28: 0.55 | C28: % of active users with active cards
A29: Card Spend per Active Card/Month ($) | B29: 850 | C29: Average monthly card spend
A30: Domestic Interchange Rate (%) | B30: 0.0115 | C30: 1.15% average interchange
A31: International Card Spend % of Total | B31: 0.25 | C31: 25% spent internationally
A32: International Interchange Rate (%) | B32: 0.0165 | C32: 1.65% on international
A33: ATM Withdrawals per Card/Month | B33: 1.2 | C33: Average ATM usage
A34: ATM Fee per Withdrawal ($) | B34: 2.5 | C34: Fee per ATM transaction
A36: LENDING & CREDIT REVENUE
A37: Loan Penetration Rate (%) | B37: 0.18 | C37: % of active users with loans
A38: Avg Loan Balance per Borrower ($) | B38: 3500 | C38: Average outstanding balance
A39: Annual Interest Rate (%) | B39: 0.189 | C39: 18.9% APR average
A40: Loan Origination Fee (%) | B40: 0.025 | C40: 2.5% origination fee
A42: Credit Line Penetration (%) | B42: 0.08 | C42: % with credit lines
A43: Avg Credit Line Size ($) | B43: 2000 | C43: Average credit limit
A44: Credit Line Utilization (%) | B44: 0.45 | C44: % of limit used
A45: Credit Line APR (%) | B45: 0.229 | C45: 22.9% APR on credit lines
A47: Buy Now Pay Later (BNPL) Penetration | B47: 0.25 | C47: % using BNPL
...

Sheet Unit Economics
A1: UNIT ECONOMICS - PER ACTIVE USER PER MONTH
A2: Monthly Revenue & Costs per Active User
A4: REVENUE PER ACTIVE USER
A5: Transaction Fees - Domestic | B5: ='Revenue Model'!B17*'Revenue Model'!B18*'Revenue Model'!B19*(1-'Revenue Model'!B20) -> 0.000144375
A6: Transaction Fees - International | B6: ='Revenue Model'!B17*'Revenue Model'!B18*('Revenue Model'!B19+'Revenue Model'!B21)*'Revenue Model'!B20 -> 0
A7: FX Spread - Fiat | B7: ='Revenue Model'!B23*'Revenue Model'!B24*'Revenue Model'!B25*(1-'Revenue Model'!B26) -> 3e-05
A8: FX Spread - Crypto | B8: ='Revenue Model'!B23*'Revenue Model'!B24*'Revenue Model'!B27*'Revenue Model'!B26 -> 0
A9: Interchange - Domestic Cards | B9: ='Revenue Model'!B31*'Revenue Model'!B32*'Revenue Model'!B33*(1-'Revenue Model'!B34) -> -0.007425
A10: Interchange - International Cards | B10: ='Revenue Model'!B31*'Revenue Model'!B32*'Revenue Model'!B35*'Revenue Model'!B34 -> 0
A11: ATM Fee Income | B11: ='Revenue Model'!B31*'Revenue Model'!B36*'Revenue Model'!B37 -> 0
A12: Loan Interest (Monthly) | B12: ='Revenue Model'!B41*'Revenue Model'!B42*'Revenue Model'!B43/12 -> 0
A13: Loan Origination Fees (Monthly) | B13: ='Revenue Model'!B41*'Revenue Model'!B42*'Revenue Model'!B44/12 -> 0
A14: Credit Line Interest | B14: ='Revenue Model'!B46*'Revenue Model'!B47*'Revenue Model'!B48*'Revenue Model'!B49/12 -> 0
A15: BNPL Merchant Fees | B15: ='Revenue Model'!B51*'Revenue Model'!B52*'Revenue Model'!B53*'Revenue Model'!B54 -> 0
A16: Premium Subscription | B16: ='Revenue Model'!B58*'Revenue Model'!B59 -> 0
A17: Net Interest Margin (Deposits) | B17: ='Revenue Model'!B61*'Revenue Model'!B62*'Revenue Model'!B63/12 -> 0.903125
A18: Investment Advisory Fees | B18: ='Revenue Model'!B66*'Revenue Model'!B67*'Revenue Model'!B68/12 -> 0
A19: Partner Referrals | B19: ='Revenue Model'!B71*'Revenue Model'!B72/12 -> 1e-06
A20: TOTAL REVENUE PER USER/MONTH | B20: =SUM(B5:B19) -> 0.89587538
A22: COSTS PER ACTIVE USER
A23: Payment Processing Costs | B23: =(B5+B6)/('Revenue Model'!B19)*('Revenue Model'!B75) -> 0.433125
A24: FX Backend Costs | B24: =(B7+B8)/('Revenue Model'!B25)*('Revenue Model'!B76) -> 0.00018
A25: Card Network Fees | B25: =(B9+B10)/('Revenue Model'!B33)*('Revenue Model'!B77) -> -0.000495
A26: Cost of Funds (Lending) | B26: ='Revenue Model'!B41*'Revenue Model'!B42*'Revenue Model'!B78/12 -> 0
A27: Loan Loss Provision | B27: ='Revenue Model'!B41*'Revenue Model'!B42*'Revenue Model'!B79/12 -> 0
A28: Technology & Infrastructure | B28: =B20*'Revenue Model'!B81 -> 0
A29: Compliance & Regulatory | B29: =B20*'Revenue Model'!B82 -> 0
A30: TOTAL COSTS PER USER/MONTH | B30: =SUM(B23:B29) -> 0.43281
A32: CONTRIBUTION MARGIN PER USER | B32: =B20-B30 -> 0.46306538
A33: Contribution Margin % | B33: =IF(B20=0,0,B32/B20) -> 0.51688593
A35: ANNUAL METRICS
A36: Annual Revenue per Active User | B36: =B20*12 -> 10.750504
A37: Customer Acquisition Cost (CAC) | B37: ='Revenue Model'!B80 -> 0
A38: Months to Recover CAC | B38: =IF(B32=0,0,B37/B32) -> 0
A39: LTV / CAC Ratio (3 year) | B39: =IF(B37=0,0,(B32*36)/B37) -> 0

Sheet Scenario Analysis
A1: SCENARIO ANALYSIS - VALUATION OUTCOMES
A2: Compare different funding scenarios and business performance
A4: SCENARIOS | B4: Conservative | C4: Base Case | D4: Growth | E4: Aggressive | F4: Optimistic
A5: FUNDING ASSUMPTIONS
A6: Pre-Money Valuation ($M) | B6: 5000000 | C6: 8000000 | D6: 12000000 | E6: 18000000 | F6: 25000000
A7: Investment Amount ($M) | B7: 1500000 | C7: 2000000 | D7: 3000000 | E7: 5000000 | F7: 8000000
A9: CALCULATED OUTCOMES
A10: Post-Money Valuation | B10: =B6+B7 -> 6500000 | C10: =C6+C7 -> 10000000 | D10: =D6+D7 -> 15000000 | E10: =E6+E7 -> 23000000 | F10: =F6+F7 -> 33000000
A11: Investor Equity % | B11: =B7/B10 -> 0.23076923 | C11: =C7/C10 -> 0.2 | D11: =D7/D10 -> 0.2 | E11: =E7/E10 -> 0.2173913 | F11: =F7/F10 -> 0.24242424
A12: Founder Dilution % | B12: =B11 -> 0.23076923 | C12: =C11 -> 0.2 | D12: =D11 -> 0.2 | E12: =E11 -> 0.2173913 | F12: =F11 -> 0.24242424
A13: $ Raised per 1% Equity | B13: =B7/B11 -> 6500000 | C13: =C7/C11 -> 10000000 | D13: =D7/D11 -> 15000000 | E13: =E7/E11 -> 23000000 | F13: =F7/F11 -> 33000000
A15: BUSINESS PERFORMANCE SCENARIOS
A16: Year 1 User Growth Multiplier | B16: 1.5 | C16: 2 | D16: 2.5 | E16: 3 | F16: 4
A17: Revenue per User Multiplier | B17: 0.8 | C17: 1 | D17: 1.2 | E17: 1.5 | F17: 2
A19: PROJECTED YEAR 1 RESULTS
A20: Total Users (Year 1) | B20: ='Revenue Model'!B5*(1+B16) -> 25000 | C20: ='Revenue Model'!B5*(1+C16) -> 30000 | D20: ='Revenue Model'!B5*(1+D16) -> 35000 | E20: ='Revenue Model'!B5*(1+E16) -> 40000 | F20: ='Revenue Model'!B5*(1+F16) -> 50000
A21: Monthly Active Users | B21: =B20*'Revenue Model'!$B$11 -> 16250 | C21: =C20*'Revenue Model'!$B$11 -> 19500 | D21: =D20*'Revenue Model'!$B$11 -> 22750 | E21: =E20*'Revenue Model'!$B$11 -> 26000 | F21: =F20*'Revenue Model'!$B$11 -> 32500
A22: Annual Revenue | B22: ='Unit Economics'!B20*B21*12*B17 -> 139756.56 | C22: ='Unit Economics'!B20*C21*12*C17 -> 209634.84 | D22: ='Unit Economics'!B20*D21*12*D17 -> 293488.77 | E22: ='Unit Economics'!B20*E21*12*E17 -> 419269.68 | F22: ='Unit Economics'!B20*F21*12*F17 -> 698782.79
A23: Revenue / Valuation Multiple | B23: =B10/B22 -> 46.509445 | C23: =C10/C22 -> 47.701995 | D23: =D10/D22 -> 51.10928 | E23: =E10/E22 -> 54.857294 | F23: =F10/F22 -> 47.224975
A25: SCENARIO ASSESSMENT
A26: Capital Efficiency Rating | B26: Weak | C26: Fair | D26: Good | E26: Strong | F26: Excellent

Sheet Valuation
A1: STARTUP VALUATION CALCULATOR
A3: CURRENT COMPANY STATUS
A4: Current Shares Outstanding | B4: 10000000
A6: FUNDING ROUND INPUTS
A7: Pre-Money Valuation ($) | B7: 8000000
A8: Investment Amount ($) | B8: 2000000
A10: CALCULATED RESULTS
A11: Post-Money Valuation | B11: =B7+B8 -> 10000000
A12: Price per Share (Pre-Money) | B12: =B7/B4 -> 0.8
A13: New Shares Issued | B13: =B8/B12 -> 2500000
A14: Total Shares Post-Money | B14: =B4+B13 -> 12500000
A15: Investor Ownership % | B15: =B13/B14 -> 0.2
A16: Founder Ownership % | B16: =B4/B14 -> 0.8

Sheet Financial Projections
A1: 5-YEAR FINANCIAL PROJECTIONS
A2: All figures in USD
B4: Year 0 | C4: Year 1 | D4: Year 2 | E4: Year 3 | F4: Year 4 | G4: Year 5
A5: USER METRICS
A6: Total Registered Users | B6: ='Revenue Model'!B5 -> 10000 | C6: =B6*(1+'Revenue Model'!B6) -> 30000 | D6: =C6*(1+'Revenue Model'!B7) -> 75000 | E6: =D6*(1+'Revenue Model'!B8) -> 150000 | F6: =E6*(1+'Revenue Model'!B9) -> 240000 | G6: =F6*(1+'Revenue Model'!B10) -> 336000
A7: Monthly Active Users (MAU) | B7: =B6*'Revenue Model'!$B$11 -> 6500 | C7: =C6*'Revenue Model'!$B$11 -> 19500 | D7: =D6*'Revenue Model'!$B$11 -> 48750 | E7: =E6*'Revenue Model'!$B$11 -> 97500 | F7: =F6*'Revenue Model'!$B$11 -> 156000 | G7: =G6*'Revenue Model'!$B$11 -> 218400
A8: Premium Users | B8: =B7*'Revenue Model'!$B$12 -> 780 | C8: =C7*'Revenue Model'!$B$12 -> 2340 | D8: =D7*'Revenue Model'!$B$12 -> 5850 | E8: =E7*'Revenue Model'!$B$12 -> 11700 | F8: =F7*'Revenue Model'!$B$12 -> 18720 | G8: =G7*'Revenue Model'!$B$12 -> 26208
A10: ANNUAL REVENUE BY STREAM
A11: Transaction Fees | B11: =('Unit Economics'!B5+'Unit Economics'!B6)*B7*12 -> 11.26125 | C11: =('Unit Economics'!B5+'Unit Economics'!B6)*C7*12 -> 33.78375 | D11: =('Unit Economics'!B5+'Unit Economics'!B6)*D7*12 -> 84.459375 | E11: =('Unit Economics'!B5+'Unit Economics'!B6)*E7*12 -> 168.91875 | F11: =('Unit Economics'!B5+'Unit Economics'!B6)*F7*12 -> 270.27 | G11: =('Unit Economics'!B5+'Unit Economics'!B6)*G7*12 -> 378.378
A12: FX Spread Revenue | B12: =('Unit Economics'!B7+'Unit Economics'!B8)*B7*12 -> 2.34 | C12: =('Unit Economics'!B7+'Unit Economics'!B8)*C7*12 -> 7.02 | D12: =('Unit Economics'!B7+'Unit Economics'!B8)*D7*12 -> 17.55 | E12: =('Unit Economics'!B7+'Unit Economics'!B8)*E7*12 -> 35.1 | F12: =('Unit Economics'!B7+'Unit Economics'!B8)*F7*12 -> 56.16 | G12: =('Unit Economics'!B7+'Unit Economics'!B8)*G7*12 -> 78.624
A13: Interchange Fees | B13: =('Unit Economics'!B9+'Unit Economics'!B10+'Unit Economics'!B11)*B7*12 -> -579.15 | C13: =('Unit Economics'!B9+'Unit Economics'!B10+'Unit Economics'!B11)*C7*12 -> -1737.45 | D13: =('Unit Economics'!B9+'Unit Economics'!B10+'Unit Economics'!B11)*D7*12 -> -4343.625 | E13: =('Unit Economics'!B9+'Unit Economics'!B10+'Unit Economics'!B11)*E7*12 -> -8687.25 | F13: =('Unit Economics'!B9+'Unit Economics'!B10+'Unit Economics'!B11)*F7*12 -> -13899.6 | G13: =('Unit Economics'!B9+'Unit Economics'!B10+'Unit Economics'!B11)*G7*12 -> -19459.44
A14: Lending Revenue | B14: =('Unit Economics'!B12+'Unit Economics'!B13+'Unit Economics'!B14)*B7*12 -> 0 | C14: =('Unit Economics'!B12+'Unit Economics'!B13+'Unit Economics'!B14)*C7*12 -> 0 | D14: =('Unit Economics'!B12+'Unit Economics'!B13+'Unit Economics'!B14)*D7*12 -> 0 | E14: =('Unit Economics'!B12+'Unit Economics'!B13+'Unit Economics'!B14)*E7*12 -> 0 | F14: =('Unit Economics'!B12+'Unit Economics'!B13+'Unit Economics'!B14)*F7*12 -> 0 | G14: =('Unit Economics'!B12+'Unit Economics'!B13+'Unit Economics'!B14)*G7*12 -> 0
A15: BNPL Merchant Fees | B15: =('Unit Economics'!B15)*B7*12 -> 0 | C15: =('Unit Economics'!B15)*C7*12 -> 0 | D15: =('Unit Economics'!B15)*D7*12 -> 0 | E15: =('Unit Economics'!B15)*E7*12 -> 0 | F15: =('Unit Economics'!B15)*F7*12 -> 0 | G15: =('Unit Economics'!B15)*G7*12 -> 0
A16: Subscription Revenue | B16: =('Unit Economics'!B16)*B7*12 -> 0 | C16: =('Unit Economics'!B16)*C7*12 -> 0 | D16: =('Unit Economics'!B16)*D7*12 -> 0 | E16: =('Unit Economics'!B16)*E7*12 -> 0 | F16: =('Unit Economics'!B16)*F7*12 -> 0 | G16: =('Unit Economics'!B16)*G7*12 -> 0
A17: Net Interest Income | B17: =('Unit Economics'!B17)*B7*12 -> 70443.75 | C17: =('Unit Economics'!B17)*C7*12 -> 211331.25 | D17: =('Unit Economics'!B17)*D7*12 -> 528328.12 | E17: =('Unit Economics'!B17)*E7*12 -> 1056656.2 | F17: =('Unit Economics'!B17)*F7*12 -> 1690650 | G17: =('Unit Economics'!B17)*G7*12 -> 2366910
A18: Investment Advisory | B18: =('Unit Economics'!B18)*B7*12 -> 0 | C18: =('Unit Economics'!B18)*C7*12 -> 0 | D18: =('Unit Economics'!B18)*D7*12 -> 0 | E18: =('Unit Economics'!B18)*E7*12 -> 0 | F18: =('Unit Economics'!B18)*F7*12 -> 0 | G18: =('Unit Economics'!B18)*G7*12 -> 0
A19: Partner Referrals | B19: =('Unit Economics'!B19)*B7*12 -> 0.078 | C19: =('Unit Economics'!B19)*C7*12 -> 0.234 | D19: =('Unit Economics'!B19)*D7*12 -> 0.585 | E19: =('Unit Economics'!B19)*E7*12 -> 1.17 | F19: =('Unit Economics'!B19)*F7*12 -> 1.872 | G19: =('Unit Economics'!B19)*G7*12 -> 2.6208
A20: TOTAL REVENUE | B20: =SUM(B12:B19) -> 69867.018 | C20: =SUM(C12:C19) -> 209601.05 | D20: =SUM(D12:D19) -> 524002.64 | E20: =SUM(E12:E19) -> 1048005.3 | F20: =SUM(F12:F19) -> 1676808.4 | G20: =SUM(G12:G19) -> 2347531.8
A22: OPERATING EXPENSES
A23: Variable Costs | B23: =('Unit Economics'!B23+'Unit Economics'!B24+'Unit Economics'!B25+'Unit Economics'!B26+'Unit Economics'!B27)*B7*12 -> 33759.18 | C23: =('Unit Economics'!B23+'Unit Economics'!B24+'Unit Economics'!B25+'Unit Economics'!B26+'Unit Economics'!B27)*C7*12 -> 101277.54 | D23: =('Unit Economics'!B23+'Unit Economics'!B24+'Unit Economics'!B25+'Unit Economics'!B26+'Unit Economics'!B27)*D7*12 -> 253193.85 | E23: =('Unit Economics'!B23+'Unit Economics'!B24+'Unit Economics'!B25+'Unit Economics'!B26+'Unit Economics'!B27)*E7*12 -> 506387.7 | F23: =('Unit Economics'!B23+'Unit Economics'!B24+'Unit Economics'!B25+'Unit Economics'!B26+'Unit Economics'!B27)*F7*12 -> 810220.32 | G23: =('Unit Economics'!B23+'Unit Economics'!B24+'Unit Economics'!B25+'Unit Economics'!B26+'Unit Economics'!B27)*G7*12 -> 1134308.4
A24: Technology & Infrastructure | B24: ='Unit Economics'!B28*B7*12 -> 0 | C24: ='Unit Economics'!B28*C7*12 -> 0 | D24: ='Unit Economics'!B28*D7*12 -> 0 | E24: ='Unit Economics'!B28*E7*12 -> 0 | F24: ='Unit Economics'!B28*F7*12 -> 0 | G24: ='Unit Economics'!B28*G7*12 -> 0
A25: Compliance & Regulatory | B25: ='Unit Economics'!B29*B7*12 -> 0 | C25: ='Unit Economics'!B29*C7*12 -> 0 | D25: ='Unit Economics'!B29*D7*12 -> 0 | E25: ='Unit Economics'!B29*E7*12 -> 0 | F25: ='Unit Economics'!B29*F7*12 -> 0 | G25: ='Unit Economics'!B29*G7*12 -> 0
A26: Customer Acquisition | B26: ='Revenue Model'!B80*B6 -> 0 | C26: ='Revenue Model'!B80*(C6-B6) -> 0 | D26: ='Revenue Model'!B80*(D6-C6) -> 0 | E26: ='Revenue Model'!B80*(E6-D6) -> 0 | F26: ='Revenue Model'!B80*(F6-E6) -> 0 | G26: ='Revenue Model'!B80*(G6-F6) -> 0
A27: Salaries & Benefits | B27: 500000 | C27: 750000 | D27: 1200000 | E27: 1800000 | F27: 2500000 | G27: 3500000
A28: Marketing & Sales | B28: 150000 | C28: 300000 | D28: 600000 | E28: 1000000 | F28: 1500000 | G28: 2200000
A29: General & Administrative | B29: 200000 | C29: 350000 | D29: 550000 | E29: 800000 | F29: 1100000 | G29: 1500000
A30: TOTAL OPERATING EXPENSES | B30: =SUM(B24:B29) -> 850000 | C30: =SUM(C24:C29) -> 1400000 | D30: =SUM(D24:D29) -> 2350000 | E30: =SUM(E24:E29) -> 3600000 | F30: =SUM(F24:F29) -> 5100000 | G30: =SUM(G24:G29) -> 7200000
A32: PROFITABILITY
A33: EBITDA | B33: =B21-B31 -> 0 | C33: =C21-C31 -> 0 | D33: =D21-D31 -> 0 | E33: =E21-E31 -> 0 | F33: =F21-F31 -> 0 | G33: =G21-G31 -> 0
A34: EBITDA Margin % | B34: =IF(B21=0,0,B34/B21) -> 0 | C34: =IF(C21=0,0,C34/C21) -> 0 | D34: =IF(D21=0,0,D34/D21) -> 0 | E34: =IF(E21=0,0,E34/E21) -> 0 | F34: =IF(F21=0,0,F34/F21) -> 0 | G34: =IF(G21=0,0,G34/G21) -> 0
